Workbook

Sheet Post
A1: Post ID | B1: Platform | C1: Date | D1: Content Type | E1: Post Text | F1: Likes | G1: Shares | H1: Comments | I1: Impressions | J1: Reach | K1: Clicks | L1: Hashtags_1 | M1: Hashtags_2 | N1: Engagement_Rate
A2: P001 | B2: Twitter | C2: 2024-12-23 | D2: Reel | E2: Explore the latest reel on Myntra! Trendy styles await. | F2: 1461 | G2: 184 | H2: 344 | I2: 21915 | J2: 21675 | K2: 15 | L2: #MyntraSale | N2: 8.06
A3: P002 | B3: Twitter | C3: 2025-04-03 | D3: Text | E3: Explore the latest text on Myntra! Trendy styles await. | F3: 4054 | G3: 389 | H3: 493 | I3: 64864 | J3: 64383 | K3: 117 | L3: #MyntraFashion | N3: 4.98
A4: P003 | B4: YouTube | C4: 2025-05-12 | D4: Reel | E4: Explore the latest reel on Myntra! Trendy styles await. | F4: 2795 | G4: 105 | H4: 49 | I4: 53105 | J4: 52307 | K4: 204 | L4: #MyntraFashion | M4: #MyntraSale | N4: 8.31
A5: P004 | B5: Instagram | C5: 2024-08-12 | D5: Story | E5: Explore the latest story on Myntra! Trendy styles await. | F5: 2404 | G5: 363 | H5: 138 | I5: 19232 | J5: 18636 | K5: 128 | L5: #MyntraSale | N5: 4.11
A6: P005 | B6: YouTube | C6: 2024-06-26 | D6: Reel | E6: Explore the latest reel on Myntra! Trendy styles await. | F6: 3557 | G6: 687 | H6: 424 | I6: 71140 | J6: 70701 | K6: 224 | L6: #StyleWithMyntra | M6: #MyntraFashion | N6: 9.05
A7: P006 | B7: Facebook | C7: 2024-10-31 | D7: Carousel | E7: Explore the latest carousel on Myntra! Trendy styles await. | F7: 2945 | G7: 930 | H7: 355 | I7: 23560 | J7: 23275 | K7: 256 | L7: #MyntraTrend | N7: 2.37
A8: P007 | B8: Twitter | C8: 2024-06-24 | D8: Carousel | E8: Explore the latest carousel on Myntra! Trendy styles await. | F8: 3860 | G8: 201 | H8: 279 | I8: 61760 | J8: 61660 | K8: 235 | L8: #MyntraTrend | N8: 4.01
A9: P008 | B9: YouTube | C9: 2024-07-13 | D9: Image | E9: Explore the latest image on Myntra! Trendy styles await. | F9: 3929 | G9: 262 | H9: 278 | I9: 43219 | J9: 42841 | K9: 39 | L9: #MyntraFashion | M9: #MyntraSale | N9: 3.16
A10: P009 | B10: Facebook | C10: 2024-08-30 | D10: Text | E10: Explore the latest text on Myntra! Trendy styles await. | F10: 3784 | G10: 808 | H10: 404 | I10: 56760 | J10: 56343 | K10: 131 | L10: #MyntraFashion | M10: #MyntraSale | N10: 2.46
A11: P010 | B11: Facebook | C11: 2025-03-11 | D11: Image | E11: Explore the latest image on Myntra! Trendy styles await. | F11: 4241 | G11: 902 | H11: 47 | I11: 72097 | J11: 71598 | K11: 167 | L11: #MyntraTrend | N11: 8.11
A12: P011 | B12: Instagram | C12: 2025-02-02 | D12: Story | E12: Explore the latest story on Myntra! Trendy styles await. | F12: 1792 | G12: 614 | H12: 497 | I12: 25088 | J12: 24675 | K12: 65 | L12: #StyleWithMyntra | N12: 8.19
A13: P012 | B13: Facebook | C13: 2024-07-21 | D13: Reel | E13: Explore the latest reel on Myntra! Trendy styles await. | F13: 1946 | G13: 686 | H13: 377 | I13: 23352 | J13: 22982 | K13: 213 | L13: #StyleWithMyntra | M13: #MyntraSale | N13: 3.49
A14: P013 | B14: YouTube | C14: 2024-11-18 | D14: Carousel | E14: Explore the latest carousel on Myntra! Trendy styles await. | F14: 1171 | G14: 286 | H14: 231 | I14: 22249 | J14: 21282 | K14: 114 | L14: #MyntraFashion | N14: 6.92
A15: P014 | B15: Facebook | C15: 2025-02-16 | D15: Story | E15: Explore the latest story on Myntra! Trendy styles await. | F15: 4242 | G15: 555 | H15: 131 | I15: 33936 | J15: 33802 | K15: 265 | L15: #MyntraSale | M15: #MyntraFashion | N15: 9.12
A16: P015 | B16: Facebook | C16: 2024-10-24 | D16: Video | E16: Explore the latest video on Myntra! Trendy styles await. | F16: 3888 | G16: 604 | H16: 128 | I16: 77760 | J16: 77167 | K16: 20 | L16: #MyntraFashion | M16: #FashionDeals | N16: 3.5
A17: P016 | B17: Facebook | C17: 2024-08-26 | D17: Text | E17: Explore the latest text on Myntra! Trendy styles await. | F17: 3452 | G17: 377 | H17: 360 | I17: 55232 | J17: 55075 | K17: 87 | L17: #MyntraSale | M17: #FashionDeals | N17: 2.62
A18: P017 | B18: Facebook | C18: 2025-05-05 | D18: Text | E18: Explore the latest text on Myntra! Trendy styles await. | F18: 4441 | G18: 511 | H18: 70 | I18: 53292 | J18: 53082 | K18: 159 | L18: #FashionDeals | N18: 9.36
A19: P018 | B19: Instagram | C19: 2024-08-19 | D19: Reel | E19: Explore the latest reel on Myntra! Trendy styles await. | F19: 3000 | G19: 382 | H19: 325 | I19: 36000 | J19: 35819 | K19: 19 | L19: #StyleWithMyntra | N19: 4.48
A20: P019 | B20: Instagram | C20: 2024-06-23 | D20: Video | E20: Explore the latest video on Myntra! Trendy styles await. | F20: 1071 | G20: 519 | H20: 22 | I20: 16065 | J20: 15865 | K20: 103 | L20: #MyntraSale | M20: #StyleWithMyntra | N20: 6.19
A21: P020 | B21: Instagram | C21: 2024-09-09 | D21: Carousel | E21: Explore the latest carousel on Myntra! Trendy styles await. | F21: 4054 | G21: 488 | H21: 373 | I21: 77026 | J21: 76881 | K21: 25 | L21: #MyntraFashion | M21: #MyntraSale | N21: 8.72
A22: P021 | B22: Instagram | C22: 2025-01-04 | D22: Reel | E22: Explore the latest reel on Myntra! Trendy styles await. | F22: 4838 | G22: 640 | H22: 128 | I22: 72570 | J22: 72396 | K22: 83 | L22: #StyleWithMyntra | M22: #MyntraTrend | N22: 8.74
A23: P022 | B23: Facebook | C23: 2025-02-27 | D23: Text | E23: Explore the latest text on Myntra! Trendy styles await. | F23: 1570 | G23: 187 | H23: 260 | I23: 25120 | J23: 24613 | K23: 133 | L23: #MyntraSale | N23: 1.91
A24: P023 | B24: Facebook | C24: 2024-11-06 | D24: Video | E24: Explore the latest video on Myntra! Trendy styles await. | F24: 1606 | G24: 547 | H24: 316 | I24: 32120 | J24: 31736 | K24: 225 | L24: #MyntraSale | N24: 4.66
A25: P024 | B25: Facebook | C25: 2025-01-23 | D25: Video | E25: Explore the latest video on Myntra! Trendy styles await. | F25: 3961 | G25: 761 | H25: 131 | I25: 67337 | J25: 66615 | K25: 161 | L25: #MyntraTrend | N25: 2.88
A26: P025 | B26: Twitter | C26: 2025-04-10 | D26: Carousel | E26: Explore the latest carousel on Myntra! Trendy styles await. | F26: 3128 | G26: 211 | H26: 197 | I26: 59432 | J26: 59182 | K26: 238 | L26: #StyleWithMyntra | M26: #MyntraSale | N26: 3.74
A27: P026 | B27: YouTube | C27: 2025-04-05 | D27: Reel | E27: Explore the latest reel on Myntra! Trendy styles await. | F27: 3009 | G27: 413 | H27: 358 | I27: 42126 | J27: 41309 | K27: 211 | L27: #MyntraSale | N27: 6.44
A28: P027 | B28: YouTube | C28: 2024-09-17 | D28: Text | E28: Explore the latest text on Myntra! Trendy styles await. | F28: 2076 | G28: 195 | H28: 104 | I28: 33216 | J28: 32244 | K28: 51 | L28: #MyntraTrend | N28: 8.56
A29: P028 | B29: Instagram | C29: 2025-03-04 | D29: Video | E29: Explore the latest video on Myntra! Trendy styles await. | F29: 432 | G29: 624 | H29: 123 | I29: 6912 | J29: 6259 | K29: 79 | L29: #MyntraSale | M29: #MyntraTrend | N29: 4.56
A30: P029 | B30: Instagram | C30: 2025-01-31 | D30: Carousel | E30: Explore the latest carousel on Myntra! Trendy styles await. | F30: 2566 | G30: 118 | H30: 37 | I30: 12830 | J30: 12264 | K30: 221 | L30: #MyntraTrend | M30: #MyntraFashion | N30: 7.88
A31: P030 | B31: Instagram | C31: 2025-02-25 | D31: Video | E31: Explore the latest video on Myntra! Trendy styles await. | F31: 3095 | G31: 39 | H31: 78 | I31: 55710 | J31: 54808 | K31: 93 | L31: #MyntraSale | N31: 7.86
A32: P031 | B32: Instagram | C32: 2024-12-16 | D32: Text | E32: Explore the latest text on Myntra! Trendy styles await. | F32: 438 | G32: 153 | H32: 275 | I32: 3066 | J32: 2701 | K32: 282 | L32: #MyntraTrend | N32: 5.34
A33: P032 | B33: Twitter | C33: 2024-07-31 | D33: Carousel | E33: Explore the latest carousel on Myntra! Trendy styles await. | F33: 2278 | G33: 10 | H33: 321 | I33: 13668 | J33: 12676 | K33: 275 | L33: #MyntraTrend | M33: #MyntraFashion | N33: 5.52
A34: P033 | B34: Facebook | C34: 2024-08-21 | D34: Image | E34: Explore the latest image on Myntra! Trendy styles await. | F34: 1407 | G34: 400 | H34: 351 | I34: 16884 | J34: 15954 | K34: 113 | L34: #MyntraFashion | M34: #FashionDeals | N34: 4.05
A35: P034 | B35: Facebook | C35: 2025-03-26 | D35: Text | E35: Explore the latest text on Myntra! Trendy styles await. | F35: 1652 | G35: 89 | H35: 357 | I35: 29736 | J35: 28771 | K35: 215 | L35: #MyntraTrend | M35: #FashionDeals | N35: 7.73
A36: P035 | B36: Instagram | C36: 2024-11-30 | D36: Video | E36: Explore the latest video on Myntra! Trendy styles await. | F36: 3775 | G36: 16 | H36: 239 | I36: 33975 | J36: 33310 | K36: 271 | L36: #StyleWithMyntra | M36: #MyntraSale | N36: 4.36
A37: P036 | B37: Instagram | C37: 2025-04-19 | D37: Story | E37: Explore the latest story on Myntra! Trendy styles await. | F37: 4518 | G37: 285 | H37: 383 | I37: 67770 | J37: 67621 | K37: 31 | L37: #FashionDeals | N37: 3.48
A38: P037 | B38: Facebook | C38: 2025-01-06 | D38: Carousel | E38: Explore the latest carousel on Myntra! Trendy styles await. | F38: 3024 | G38: 925 | H38: 350 | I38: 24192 | J38: 23518 | K38: 36 | L38: #MyntraSale | N38: 7.83
A39: P038 | B39: YouTube | C39: 2025-02-17 | D39: Reel | E39: Explore the latest reel on Myntra! Trendy styles await. | F39: 3138 | G39: 123 | H39: 291 | I39: 28242 | J39: 27550 | K39: 87 | L39: #FashionDeals | N39: 6.11
A40: P039 | B40: Facebook | C40: 2024-11-25 | D40: Image | E40: Explore the latest image on Myntra! Trendy styles await. | F40: 3564 | G40: 629 | H40: 177 | I40: 60588 | J40: 59627 | K40: 92 | L40: #FashionDeals | M40: #MyntraSale | N40: 9.43
...

Sheet Pivot Table 6
A10: Notes:-
A11: Story content has the highest engagement_rate on Youtube.
A12: Carousel and Image both have strong performance on the Instagram.

Sheet Pivot Table 5

Sheet Hashtags_Performance

Sheet Hashtags_long
A1: Post ID | B1: Clicks | C1: Hashtags | D1: Likes | E1: Comments | F1: Engagement_Rate
A2: P001 | B2: 12 | C2: #MyntraSale | D2: {=INDEX(Post!F:F, MATCH(A2, Post!A:A, 0))} -> 1461 | E2: {=INDEX(Post!G:G, MATCH(A2, Post!A:A, 0))} -> 184 | F2: {=INDEX(Post!N:N, MATCH(A2, Post!A:A, 0))} -> 8.06
A3: P002 | B3: 262 | C3: #MyntraFashion | D3: {=INDEX(Post!F:F, MATCH(A3, Post!A:A, 0))} -> 4054 | E3: {=INDEX(Post!G:G, MATCH(A3, Post!A:A, 0))} -> 389 | F3: {=INDEX(Post!N:N, MATCH(A3, Post!A:A, 0))} -> 4.98
A4: P003 | B4: 201 | C4: #MyntraFashion | D4: {=INDEX(Post!F:F, MATCH(A4, Post!A:A, 0))} -> 2795 | E4: {=INDEX(Post!G:G, MATCH(A4, Post!A:A, 0))} -> 105 | F4: {=INDEX(Post!N:N, MATCH(A4, Post!A:A, 0))} -> 8.31
A5: P004 | B5: 238 | C5: #MyntraSale | D5: {=INDEX(Post!F:F, MATCH(A5, Post!A:A, 0))} -> 2404 | E5: {=INDEX(Post!G:G, MATCH(A5, Post!A:A, 0))} -> 363 | F5: {=INDEX(Post!N:N, MATCH(A5, Post!A:A, 0))} -> 4.11
A6: P005 | B6: 154 | C6: #StyleWithMyntra | D6: {=INDEX(Post!F:F, MATCH(A6, Post!A:A, 0))} -> 3557 | E6: {=INDEX(Post!G:G, MATCH(A6, Post!A:A, 0))} -> 687 | F6: {=INDEX(Post!N:N, MATCH(A6, Post!A:A, 0))} -> 9.05
A7: P006 | B7: 148 | C7: #MyntraTrend | D7: {=INDEX(Post!F:F, MATCH(A7, Post!A:A, 0))} -> 2945 | E7: {=INDEX(Post!G:G, MATCH(A7, Post!A:A, 0))} -> 930 | F7: {=INDEX(Post!N:N, MATCH(A7, Post!A:A, 0))} -> 2.37
A8: P007 | B8: 293 | C8: #MyntraTrend | D8: {=INDEX(Post!F:F, MATCH(A8, Post!A:A, 0))} -> 3860 | E8: {=INDEX(Post!G:G, MATCH(A8, Post!A:A, 0))} -> 201 | F8: {=INDEX(Post!N:N, MATCH(A8, Post!A:A, 0))} -> 4.01
A9: P008 | B9: 117 | C9: #MyntraFashion | D9: {=INDEX(Post!F:F, MATCH(A9, Post!A:A, 0))} -> 3929 | E9: {=INDEX(Post!G:G, MATCH(A9, Post!A:A, 0))} -> 262 | F9: {=INDEX(Post!N:N, MATCH(A9, Post!A:A, 0))} -> 3.16
A10: P009 | B10: 287 | C10: #MyntraFashion | D10: {=INDEX(Post!F:F, MATCH(A10, Post!A:A, 0))} -> 3784 | E10: {=INDEX(Post!G:G, MATCH(A10, Post!A:A, 0))} -> 808 | F10: {=INDEX(Post!N:N, MATCH(A10, Post!A:A, 0))} -> 2.46
A11: P010 | B11: 43 | C11: #MyntraTrend | D11: {=INDEX(Post!F:F, MATCH(A11, Post!A:A, 0))} -> 4241 | E11: {=INDEX(Post!G:G, MATCH(A11, Post!A:A, 0))} -> 902 | F11: {=INDEX(Post!N:N, MATCH(A11, Post!A:A, 0))} -> 8.11
A12: P011 | B12: 282 | C12: #StyleWithMyntra | D12: {=INDEX(Post!F:F, MATCH(A12, Post!A:A, 0))} -> 1792 | E12: {=INDEX(Post!G:G, MATCH(A12, Post!A:A, 0))} -> 614 | F12: {=INDEX(Post!N:N, MATCH(A12, Post!A:A, 0))} -> 8.19
A13: P012 | B13: 11 | C13: #StyleWithMyntra | D13: {=INDEX(Post!F:F, MATCH(A13, Post!A:A, 0))} -> 1946 | E13: {=INDEX(Post!G:G, MATCH(A13, Post!A:A, 0))} -> 686 | F13: {=INDEX(Post!N:N, MATCH(A13, Post!A:A, 0))} -> 3.49
... A301: P300 | B301: 125 | C301: #MyntraFashion | D301: {=INDEX(Post!F:F, MATCH(A301, Post!A:A, 0))} -> 4494 | E301: {=INDEX(Post!G:G, MATCH(A301, Post!A:A, 0))} -> 717 | F301: {=INDEX(Post!N:N, MATCH(A301, Post!A:A, 0))}
A302: P001 | B302: 15 | D302: {=INDEX(Post!F:F, MATCH(A302, Post!A:A, 0))} -> 1461 | E302: {=INDEX(Post!G:G, MATCH(A302, Post!A:A, 0))} -> 184 | F302: {=INDEX(Post!N:N, MATCH(A302, Post!A:A, 0))} -> 8.06
A303: P002 | B303: 117 | D303: {=INDEX(Post!F:F, MATCH(A303, Post!A:A, 0))} -> 4054 | E303: {=INDEX(Post!G:G, MATCH(A303, Post!A:A, 0))} -> 389 | F303: {=INDEX(Post!N:N, MATCH(A303, Post!A:A, 0))} -> 4.98
A304: P003 | B304: 204 | C304: #MyntraSale | D304: {=INDEX(Post!F:F, MATCH(A304, Post!A:A, 0))} -> 2795 | E304: {=INDEX(Post!G:G, MATCH(A304, Post!A:A, 0))} -> 105 | F304: {=INDEX(Post!N:N, MATCH(A304, Post!A:A, 0))} -> 8.31
A305: P004 | B305: 128 | D305: {=INDEX(Post!F:F, MATCH(A305, Post!A:A, 0))} -> 2404 | E305: {=INDEX(Post!G:G, MATCH(A305, Post!A:A, 0))} -> 363 | F305: {=INDEX(Post!N:N, MATCH(A305, Post!A:A, 0))} -> 4.11
A306: P005 | B306: 224 | C306: #MyntraFashion | D306: {=INDEX(Post!F:F, MATCH(A306, Post!A:A, 0))} -> 3557 | E306: {=INDEX(Post!G:G, MATCH(A306, Post!A:A, 0))} -> 687 | F306: {=INDEX(Post!N:N, MATCH(A306, Post!A:A, 0))} -> 9.05
A307: P006 | B307: 256 | D307: {=INDEX(Post!F:F, MATCH(A307, Post!A:A, 0))} -> 2945 | E307: {=INDEX(Post!G:G, MATCH(A307, Post!A:A, 0))} -> 930 | F307: {=INDEX(Post!N:N, MATCH(A307, Post!A:A, 0))} -> 2.37
A308: P007 | B308: 235 | D308: {=INDEX(Post!F:F, MATCH(A308, Post!A:A, 0))} -> 3860 | E308: {=INDEX(Post!G:G, MATCH(A308, Post!A:A, 0))} -> 201 | F308: {=INDEX(Post!N:N, MATCH(A308, Post!A:A, 0))} -> 4.01
A309: P008 | B309: 39 | C309: #MyntraSale | D309: {=INDEX(Post!F:F, MATCH(A309, Post!A:A, 0))} -> 3929 | E309: {=INDEX(Post!G:G, MATCH(A309, Post!A:A, 0))} -> 262 | F309: {=INDEX(Post!N:N, MATCH(A309, Post!A:A, 0))} -> 3.16
A310: P009 | B310: 131 | C310: #MyntraSale | D310: {=INDEX(Post!F:F, MATCH(A310, Post!A:A, 0))} -> 3784 | E310: {=INDEX(Post!G:G, MATCH(A310, Post!A:A, 0))} -> 808 | F310: {=INDEX(Post!N:N, MATCH(A310, Post!A:A, 0))} -> 2.46
A311: P010 | B311: 167 | D311: {=INDEX(Post!F:F, MATCH(A311, Post!A:A, 0))} -> 4241 | E311: {=INDEX(Post!G:G, MATCH(A311, Post!A:A, 0))} -> 902 | F311: {=INDEX(Post!N:N, MATCH(A311, Post!A:A, 0))} -> 8.11
A312: P011 | B312: 65 | D312: {=INDEX(Post!F:F, MATCH(A312, Post!A:A, 0))} -> 1792 | E312: {=INDEX(Post!G:G, MATCH(A312, Post!A:A, 0))} -> 614 | F312: {=INDEX(Post!N:N, MATCH(A312, Post!A:A, 0))} -> 8.19
A313: P012 | B313: 213 | C313: #MyntraSale | D313: {=INDEX(Post!F:F, MATCH(A313, Post!A:A, 0))} -> 1946 | E313: {=INDEX(Post!G:G, MATCH(A313, Post!A:A, 0))} -> 686 | F313: {=INDEX(Post!N:N, MATCH(A313, Post!A:A, 0))} -> 3.49
A314: P013 | B314: 114 | D314: {=INDEX(Post!F:F, MATCH(A314, Post!A:A, 0))} -> 1171 | E314: {=INDEX(Post!G:G, MATCH(A314, Post!A:A, 0))} -> 286 | F314: {=INDEX(Post!N:N, MATCH(A314, Post!A:A, 0))} -> 6.92
A315: P014 | B315: 265 | C315: #MyntraFashion | D315: {=INDEX(Post!F:F, MATCH(A315, Post!A:A, 0))} -> 4242 | E315: {=INDEX(Post!G:G, MATCH(A315, Post!A:A, 0))} -> 555 | F315: {=INDEX(Post!N:N, MATCH(A315, Post!A:A, 0))} -> 9.12
A316: P015 | B316: 20 | C316: #FashionDeals | D316: {=INDEX(Post!F:F, MATCH(A316, Post!A:A, 0))} -> 3888 | E316: {=INDEX(Post!G:G, MATCH(A316, Post!A:A, 0))} -> 604 | F316: {=INDEX(Post!N:N, MATCH(A316, Post!A:A, 0))} -> 3.5
A317: P016 | B317: 87 | C317: #FashionDeals | D317: {=INDEX(Post!F:F, MATCH(A317, Post!A:A, 0))} -> 3452 | E317: {=INDEX(Post!G:G, MATCH(A317, Post!A:A, 0))} -> 377 | F317: {=INDEX(Post!N:N, MATCH(A317, Post!A:A, 0))} -> 2.62
A318: P017 | B318: 159 | D318: {=INDEX(Post!F:F, MATCH(A318, Post!A:A, 0))} -> 4441 | E318: {=INDEX(Post!G:G, MATCH(A318, Post!A:A, 0))} -> 511 | F318: {=INDEX(Post!N:N, MATCH(A318, Post!A:A, 0))} -> 9.36
A319: P018 | B319: 19 | D319: {=INDEX(Post!F:F, MATCH(A319, Post!A:A, 0))} -> 3000 | E319: {=INDEX(Post!G:G, MATCH(A319, Post!A:A, 0))} -> 382 | F319: {=INDEX(Post!N:N, MATCH(A319, Post!A:A, 0))} -> 4.48
A320: P019 | B320: 103 | C320: #StyleWithMyntra | D320: {=INDEX(Post!F:F, MATCH(A320, Post!A:A, 0))} -> 1071 | E320: {=INDEX(Post!G:G, MATCH(A320, Post!A:A, 0))} -> 519 | F320: {=INDEX(Post!N:N, MATCH(A320, Post!A:A, 0))} -> 6.19
A321: P020 | B321: 25 | C321: #MyntraSale | D321: {=INDEX(Post!F:F, MATCH(A321, Post!A:A, 0))} -> 4054 | E321: {=INDEX(Post!G:G, MATCH(A321, Post!A:A, 0))} -> 488 | F321: {=INDEX(Post!N:N, MATCH(A321, Post!A:A, 0))} -> 8.72
A322: P021 | B322: 83 | C322: #MyntraTrend | D322: {=INDEX(Post!F:F, MATCH(A322, Post!A:A, 0))} -> 4838 | E322: {=INDEX(Post!G:G, MATCH(A322, Post!A:A, 0))} -> 640 | F322: {=INDEX(Post!N:N, MATCH(A322, Post!A:A, 0))} -> 8.74
A323: P022 | B323: 133 | D323: {=INDEX(Post!F:F, MATCH(A323, Post!A:A, 0))} -> 1570 | E323: {=INDEX(Post!G:G, MATCH(A323, Post!A:A, 0))} -> 187 | F323: {=INDEX(Post!N:N, MATCH(A323, Post!A:A, 0))} -> 1.91
A324: P023 | B324: 225 | D324: {=INDEX(Post!F:F, MATCH(A324, Post!A:A, 0))} -> 1606 | E324: {=INDEX(Post!G:G, MATCH(A324, Post!A:A, 0))} -> 547 | F324: {=INDEX(Post!N:N, MATCH(A324, Post!A:A, 0))} -> 4.66
A325: P024 | B325: 161 | D325: {=INDEX(Post!F:F, MATCH(A325, Post!A:A, 0))} -> 3961 | E325: {=INDEX(Post!G:G, MATCH(A325, Post!A:A, 0))} -> 761 | F325: {=INDEX(Post!N:N, MATCH(A325, Post!A:A, 0))} -> 2.88
A326: P025 | B326: 238 | C326: #MyntraSale | D326: {=INDEX(Post!F:F, MATCH(A326, Post!A:A, 0))} -> 3128 | E326: {=INDEX(Post!G:G, MATCH(A326, Post!A:A, 0))} -> 211 | F326: {=INDEX(Post!N:N, MATCH(A326, Post!A:A, 0))} -> 3.74
A327: P026 | B327: 211 | D327: {=INDEX(Post!F:F, MATCH(A327, Post!A:A, 0))} -> 3009 | E327: {=INDEX(Post!G:G, MATCH(A327, Post!A:A, 0))} -> 413 | F327: {=INDEX(Post!N:N, MATCH(A327, Post!A:A, 0))} -> 6.44
...

Sheet Pivot Table 4

Sheet Engagment Summary
A1: Week_Start_Date | B1: Platform | C1: New_Followers | D1: Unfollows | E1: Total_Followers | F1: Engagement_Rate | G1: Ad_Spend
A2: 45446 | B2: Instagram | C2: 1135 | D2: 88 | E2: 344084 | F2: 8.06 | G2: 5904
A3: 45446 | B3: Facebook | C3: 1312 | D3: 310 | E3: 42654 | F3: 4.98 | G3: 9566
A4: 45446 | B4: Twitter | C4: 584 | D4: 169 | E4: 146834 | F4: 8.31 | G4: 26752
A5: 45446 | B5: YouTube | C5: 1535 | D5: 445 | E5: 395536 | F5: 4.11 | G5: 30671
A6: 45453 | B6: Instagram | C6: 656 | D6: 139 | E6: 49157 | F6: 9.05 | G6: 9920
A7: 45453 | B7: Facebook | C7: 1697 | D7: 414 | E7: 316555 | F7: 2.37 | G7: 7924
A8: 45453 | B8: Twitter | C8: 436 | D8: 250 | E8: 254347 | F8: 4.01 | G8: 8912
A9: 45453 | B9: YouTube | C9: 1197 | D9: 203 | E9: 413878 | F9: 3.16 | G9: 21205
A10: 45460 | B10: Instagram | C10: 1048 | D10: 155 | E10: 456946 | F10: 2.46 | G10: 11329
A11: 45460 | B11: Facebook | C11: 1753 | D11: 371 | E11: 169496 | F11: 8.11 | G11: 46670
A12: 45460 | B12: Twitter | C12: 1335 | D12: 40 | E12: 122732 | F12: 8.19 | G12: 22482
A13: 45460 | B13: YouTube | C13: 403 | D13: 66 | E13: 382851 | F13: 3.49 | G13: 24313
... A201: 45789 | B201: YouTube | C201: 119 | D201: 456 | E201: 82558 | F201: 6.81 | G201: 12174

Sheet Campaign Data
A1: Campaign_Name | B1: Start_Date | C1: End_Date | D1: Objective | E1: Total_Budget | F1: Target_Platforms
A2: EndOfSeasonSale | B2: 45453 | C2: 45478 | D2: Seasonal Clearance Promotion | E2: 180000 | F2: Instagram,Facebook
A3: FashionUpgrade | B3: 45505 | C3: 45535 | D3: Customer Engagement | E3: 160000 | F3: Instagram,YouTube
A4: MyntraFestiveEdit | B4: 45570 | C4: 45601 | D4: Festive Collection Launch | E4: 220000 | F4: Facebook,Instagram
A5: StyleRevolution | B5: 45667 | C5: 45698 | D5: Brand Awareness & Growth | E5: 200000 | F5: Instagram,Twitter
